<mujoco model="wlr_robot">
  <!-- WLR Robot — Open-chain model with PD balance controller -->
  <compiler angle="radian" autolimits="true"/>
  <option timestep="0.001" gravity="0 0 -9.81" solver="Newton" iterations="100"/>
  <default>
    <joint damping="0.02" armature="0.001"/>
    <geom contype="1" conaffinity="1" condim="4" friction="1.5 0.005 0.001"/>
  </default>
  <asset>
    <texture type="2d" name="grid" builtin="checker" width="512" height="512"
             rgb1="0.8 0.8 0.8" rgb2="0.6 0.6 0.6"/>
    <material name="grid" texture="grid" texrepeat="5 5" reflectance="0.1"/>
  </asset>
  <worldbody>
    <geom name="floor" type="plane" size="10 10 0.1" material="grid" friction="1.5 0.005 0.001"/>
    <body name="base" pos="0 0 0.267">
      <freejoint/>
      <inertial mass="0.7" pos="0 0 0" diaginertia="0.001 0.002 0.003"/>
      <geom type="box" size="0.105 0.0775 0.015" rgba="0.3 0.3 0.3 1"/>
      <site name="imu" pos="0 0 0"/>
      <!-- LEFT LEG -->
      <body name="L_hip" pos="0.0615 0.0875 0">
        <joint name="L_hip_j" type="hinge" axis="0 1 0" range="-1.5 1.5" damping="0.05"/>
        <inertial mass="0.04" pos="0 0 -0.035" diaginertia="1e-5 1e-5 1e-6"/>
        <geom type="capsule" fromto="0 0 0 0 0 -0.07" size="0.008" rgba="0.2 0.4 0.8 1"/>
        <body name="L_knee" pos="0 0 -0.07">
          <joint name="L_knee_j" type="hinge" axis="0 1 0" range="-3.14 3.14" damping="0.05"/>
          <inertial mass="0.072" pos="0 0 -0.0735" diaginertia="1.3e-4 1.3e-4 2.3e-6"/>
          <geom type="capsule" fromto="0 0 0 0 0 -0.147" size="0.008" rgba="0.7 0.7 0.7 1"/>
          <body name="L_wheel" pos="0 0 -0.147">
            <joint name="L_wheel_j" type="hinge" axis="0 1 0" damping="0.01"/>
            <inertial mass="0.34" pos="0 0 0" diaginertia="2.3e-4 4.25e-4 2.3e-4"/>
            <geom type="cylinder" fromto="0 -0.0125 0 0 0.0125 0" size="0.05"
                  rgba="0.15 0.15 0.15 1" friction="1.5 0.005 0.001"/>
          </body>
        </body>
      </body>
      <!-- RIGHT LEG -->
      <body name="R_hip" pos="0.0615 -0.0875 0">
        <joint name="R_hip_j" type="hinge" axis="0 1 0" range="-1.5 1.5" damping="0.05"/>
        <inertial mass="0.04" pos="0 0 -0.035" diaginertia="1e-5 1e-5 1e-6"/>
        <geom type="capsule" fromto="0 0 0 0 0 -0.07" size="0.008" rgba="0.2 0.4 0.8 1"/>
        <body name="R_knee" pos="0 0 -0.07">
          <joint name="R_knee_j" type="hinge" axis="0 1 0" range="-3.14 3.14" damping="0.05"/>
          <inertial mass="0.072" pos="0 0 -0.0735" diaginertia="1.3e-4 1.3e-4 2.3e-6"/>
          <geom type="capsule" fromto="0 0 0 0 0 -0.147" size="0.008" rgba="0.7 0.7 0.7 1"/>
          <body name="R_wheel" pos="0 0 -0.147">
            <joint name="R_wheel_j" type="hinge" axis="0 1 0" damping="0.01"/>
            <inertial mass="0.34" pos="0 0 0" diaginertia="2.3e-4 4.25e-4 2.3e-4"/>
            <geom type="cylinder" fromto="0 -0.0125 0 0 0.0125 0" size="0.05"
                  rgba="0.15 0.15 0.15 1" friction="1.5 0.005 0.001"/>
          </body>
        </body>
      </body>
    </body>
  </worldbody>
  <actuator>
    <motor name="L_hip_m"   joint="L_hip_j"   gear="1" ctrlrange="-10 10" ctrllimited="true"/>
    <motor name="L_knee_m"  joint="L_knee_j"  gear="1" ctrlrange="-50 50" ctrllimited="true"/>
    <motor name="L_wheel_m" joint="L_wheel_j"  gear="1" ctrlrange="-10 10" ctrllimited="true"/>
    <motor name="R_hip_m"   joint="R_hip_j"   gear="1" ctrlrange="-10 10" ctrllimited="true"/>
    <motor name="R_knee_m"  joint="R_knee_j"  gear="1" ctrlrange="-50 50" ctrllimited="true"/>
    <motor name="R_wheel_m" joint="R_wheel_j"  gear="1" ctrlrange="-10 10" ctrllimited="true"/>
  </actuator>
  <sensor>
    <framequat name="quat" objtype="site" objname="imu"/>
    <gyro name="gyro" site="imu"/>
  </sensor>
</mujoco>
